Workbook

Sheet 99
A1: Nome do item
A2: Refrigerante Pepsi Zero 2L
A3: Refrigerante Coca-Cola Lata Com 350ml
A4: Refresco H2oh Limoneto 1,5l
A5: Suco Del Valle Frut Laranja 1,5L
A6: Refrigerante Fanta Laranja 350ML
A7: Refrigerante Guaraná Antarctica Zero 350ML
A8: Cerveja Heineken Garrafa 330ml
A9: Whisky Escocês White Horse 1L
A10: Rum Bacardí Carta Blanca 980ML
A11: Vinho Chileno Chilano Cabernet Garrafa com 750ml
A12: Cerveja Michelob Ultra Superior Light Beer Lata 350ml
... A147: Cerveja Stella Artois Pure Gold Lt 269ml

Sheet CUSTOS
A1: PRODUTO
A2: CARVÃO SELEÇÃO 4KG
A3: CARVÃO SELEÇÃO 8KG
A4: AMENDOIM PANCHITO
A5: QUEIJO NOZINHO
A6: AMENDOIM SEM PELE ELMA CHIPS PACOTE 100G
A7: BATATA FRITA LISA LAYS CLÁSSICA PACOTE 70G
A8: BATATA FRITA ONDULADA RUFFLES CEBOLA E SALSA PACOTE 68G
A9: BATATA FRITA ONDULADA RUFFLES CHURRASCO PACOTE 68G
A10: BATATA FRITA ONDULADA RUFFLES ORIGINAL PACOTE 115G
A11: BATATA FRITA ONDULADA RUFFLES ORIGINAL PACOTE 68G
A12: OVINHOS DE AMENDOIM ELMA CHIPS PACOTE 65G
... A702: Whisky Jack Daniels 1l Blackberry

Sheet DE PARA
A1: NOME DO ITEM (99) | B1: PRODUTO (CUSTOS) | C1: STATUS | D1: OBSERVAÇÃO | E1: LINHA EM CUSTOS
A2: ='99'!A2 -> Refrigerante Pepsi Zero 2L | B2: REFRIGERANTE PEPSI BLACK GARRAFA 2L | C2: APROXIMADO | D2: Pepsi Black é a versão zero açúcar | E2: =IF(B2="","",IFERROR(MATCH(B2,CUSTOS!$A:$A,0),"NÃO ACHOU")) -> 548
A3: ='99'!A3 -> Refrigerante Coca-Cola Lata Com 350ml | B3: REFRIGERANTE COCA COLA LATA 350ML | C3: OK | E3: =IF(B3="","",IFERROR(MATCH(B3,CUSTOS!$A:$A,0),"NÃO ACHOU")) -> 138
A4: ='99'!A4 -> Refresco H2oh Limoneto 1,5l | B4: ÁGUA SABORIZADA H2OH LIMONETO 500ML | C4: APROXIMADO | D4: CUSTOS não tem Limoneto 1,5L (só 500ml e 350ml) | E4: =IF(B4="","",IFERROR(MATCH(B4,CUSTOS!$A:$A,0),"NÃO ACHOU")) -> 20
A5: ='99'!A5 -> Suco Del Valle Frut Laranja 1,5L | B5: Suco Del Valle Frut Laranja 1,5l | C5: OK | D5: Item aparece 2x em CUSTOS | E5: =IF(B5="","",IFERROR(MATCH(B5,CUSTOS!$A:$A,0),"NÃO ACHOU")) -> 669
A6: ='99'!A6 -> Refrigerante Fanta Laranja 350ML | B6: REFRIGERANTE FANTA LARANJA LATA 350ML | C6: OK | E6: =IF(B6="","",IFERROR(MATCH(B6,CUSTOS!$A:$A,0),"NÃO ACHOU")) -> 141
A7: ='99'!A7 -> Refrigerante Guaraná Antarctica Zero 350ML | B7: REFRIGERANTE GUARANA ANTARTICA ZERO LATA 350ML | C7: OK | E7: =IF(B7="","",IFERROR(MATCH(B7,CUSTOS!$A:$A,0),"NÃO ACHOU")) -> 143
A8: ='99'!A8 -> Cerveja Heineken Garrafa 330ml | B8: CERVEJA HEINEKEN LONG 330ML | C8: OK | E8: =IF(B8="","",IFERROR(MATCH(B8,CUSTOS!$A:$A,0),"NÃO ACHOU")) -> 95
A9: ='99'!A9 -> Whisky Escocês White Horse 1L | B9: WHISKY WHITE HORSE 8 ANOS 1L | C9: OK | E9: =IF(B9="","",IFERROR(MATCH(B9,CUSTOS!$A:$A,0),"NÃO ACHOU")) -> 202
A10: ='99'!A10 -> Rum Bacardí Carta Blanca 980ML | B10: RUM BACARDI PRATA 980ML | C10: OK | D10: Carta Blanca = Prata | E10: =IF(B10="","",IFERROR(MATCH(B10,CUSTOS!$A:$A,0),"NÃO ACHOU")) -> 78
A11: ='99'!A11 -> Vinho Chileno Chilano Cabernet Garrafa com 750ml | B11: VINHO CHILANO CABERNET SAUVIGNON 750ML | C11: OK | E11: =IF(B11="","",IFERROR(MATCH(B11,CUSTOS!$A:$A,0),"NÃO ACHOU")) -> 164
A12: ='99'!A12 -> Cerveja Michelob Ultra Superior Light Beer Lata 350ml | B12: Cerveja Michelob Sleek Ultra 350ml | C12: OK | D12: Alternativa: CERVEJA MICHELOB ULTRA 355ML | E12: =IF(B12="","",IFERROR(MATCH(B12,CUSTOS!$A:$A,0),"NÃO ACHOU")) -> 679
A13: ='99'!A13 -> Vodka Absolut - 1 Litro | B13: VODKA ABSOLUT 1L | C13: OK | E13: =IF(B13="","",IFERROR(MATCH(B13,CUSTOS!$A:$A,0),"NÃO ACHOU")) -> 186
A14: ='99'!A14 -> Vinho Por Alandra Bco 750Ml | B14: VINHO ALANDRA BRANCO 750ML | C14: OK | E14: =IF(B14="","",IFERROR(MATCH(B14,CUSTOS!$A:$A,0),"NÃO ACHOU")) -> 248
A15: ='99'!A15 -> Vinho Chi Stacarolina Rsvd Rose 750Ml | B15: VINHO SANTA CAROLINA RESERVADO ROSE 750ML | C15: OK | E15: =IF(B15="","",IFERROR(MATCH(B15,CUSTOS!$A:$A,0),"NÃO ACHOU")) -> 569
A16: ='99'!A16 -> Cerveja Sol Premium Long Neck 330ml | B16: CERVEJA SOL LONG 330ML | C16: OK | E16: =IF(B16="","",IFERROR(MATCH(B16,CUSTOS!$A:$A,0),"NÃO ACHOU")) -> 102
A17: ='99'!A17 -> Cerveja Heineken Garrafa 330ml | B17: CERVEJA HEINEKEN LONG 330ML | C17: OK | E17: =IF(B17="","",IFERROR(MATCH(B17,CUSTOS!$A:$A,0),"NÃO ACHOU")) -> 95
A18: ='99'!A18 -> Bebida Alcoólica Xeque Mate 355ML | B18: RTD XEQUE MATE 355ML | C18: OK | E18: =IF(B18="","",IFERROR(MATCH(B18,CUSTOS!$A:$A,0),"NÃO ACHOU")) -> 413
A19: ='99'!A19 -> Cerveja Corona Long Neck Com 330ml | B19: CERVEJA CORONA LONG 330ML | C19: OK | E19: =IF(B19="","",IFERROR(MATCH(B19,CUSTOS!$A:$A,0),"NÃO ACHOU")) -> 90
A20: ='99'!A20 -> Bebida Energética Red Bull Lata 250 ml | B20: ENERGETICO RED BULL LATA 250ML | C20: OK | E20: =IF(B20="","",IFERROR(MATCH(B20,CUSTOS!$A:$A,0),"NÃO ACHOU")) -> 113
A21: ='99'!A21 -> Gelo Para Drink Coco Leve 190G | B21: Gelo Coco Leve Para Drink Sabor Água de Coco 190g | C21: APROXIMADO | D21: Sabor não informado; assumido sabor tradicional (água de coco) | E21: =IF(B21="","",IFERROR(MATCH(B21,CUSTOS!$A:$A,0),"NÃO ACHOU")) -> 688
A22: ='99'!A22 -> Refrigerante Guaraná Antarctica 2L | B22: REFRIGERANTE GUARANA ANTARTICA GARRAFA 2L | C22: OK | E22: =IF(B22="","",IFERROR(MATCH(B22,CUSTOS!$A:$A,0),"NÃO ACHOU")) -> 142
A23: ='99'!A23 -> Whiskey Jack Daniel's 1L | B23: WHISKY JACK DANIEL'S OLD N°07 1L | C23: OK | E23: =IF(B23="","",IFERROR(MATCH(B23,CUSTOS!$A:$A,0),"NÃO ACHOU")) -> 197
A24: ='99'!A24 -> Enos Gimenez Riili Bu Hermanos Cabernet Franc - Vinho Fino Tinto | B24: VINHO GIMENEZ RILLI BUENOS HERMANOS CABERNET 750ML | C24: APROXIMADO | D24: CUSTOS não especifica se é Cabernet Franc | E24: =IF(B24="","",IFERROR(MATCH(B24,CUSTOS!$A:$A,0),"NÃO ACHOU")) -> 230
A25: ='99'!A25 -> Vinho Arg Cordero Con Piel Lobo Rs 750Ml | B25: VINHO CORDERO CON PIEL DE LOBO ROSE MALBEC 750ML | C25: OK | E25: =IF(B25="","",IFERROR(MATCH(B25,CUSTOS!$A:$A,0),"NÃO ACHOU")) -> 271
A26: ='99'!A26 -> Refresco H2oh Limoneto 1,5l | B26: ÁGUA SABORIZADA H2OH LIMONETO 500ML | C26: APROXIMADO | D26: CUSTOS não tem Limoneto 1,5L (só 500ml e 350ml) | E26: =IF(B26="","",IFERROR(MATCH(B26,CUSTOS!$A:$A,0),"NÃO ACHOU")) -> 20
A27: ='99'!A27 -> Refrigerante Pepsi Zero 2L | B27: REFRIGERANTE PEPSI BLACK GARRAFA 2L | C27: APROXIMADO | D27: Pepsi Black é a versão zero açúcar | E27: =IF(B27="","",IFERROR(MATCH(B27,CUSTOS!$A:$A,0),"NÃO ACHOU")) -> 548
A28: ='99'!A28 -> Refrigerante Pepsi Cola 2L | B28: REFRIGERANTE PET PEPSI 2L | C28: OK | E28: =IF(B28="","",IFERROR(MATCH(B28,CUSTOS!$A:$A,0),"NÃO ACHOU")) -> 48
A29: ='99'!A29 -> Cerveja Corona Pilsen Lata 350ml | B29: CERVEJA CORONA LATA 350ML | C29: OK | E29: =IF(B29="","",IFERROR(MATCH(B29,CUSTOS!$A:$A,0),"NÃO ACHOU")) -> 595
A30: ='99'!A30 -> Cerveja Amstel Lager Lata 350ml | B30: CERVEJA AMSTEL LATA 350ML | C30: OK | E30: =IF(B30="","",IFERROR(MATCH(B30,CUSTOS!$A:$A,0),"NÃO ACHOU")) -> 82
A31: ='99'!A31 -> Cerveja Brahma Duplo Malte Lata Com 350ml | B31: CERVEJA BRAHMA DUPLO MALTE LATA 350ML | C31: OK | E31: =IF(B31="","",IFERROR(MATCH(B31,CUSTOS!$A:$A,0),"NÃO ACHOU")) -> 84
A32: ='99'!A32 -> Refresco H2oh Limoneto 1,5l | B32: ÁGUA SABORIZADA H2OH LIMONETO 500ML | C32: APROXIMADO | D32: CUSTOS não tem Limoneto 1,5L (só 500ml e 350ml) | E32: =IF(B32="","",IFERROR(MATCH(B32,CUSTOS!$A:$A,0),"NÃO ACHOU")) -> 20
A33: ='99'!A33 -> Energético Baly FrutasTropicais 2L | B33: ENERGETICO BALY TROPICAL GARRAFA 2L | C33: OK | E33: =IF(B33="","",IFERROR(MATCH(B33,CUSTOS!$A:$A,0),"NÃO ACHOU")) -> 109
A34: ='99'!A34 -> Whisky Chivas Regal 12 Anos 1L | B34: WHISKY CHIVAS REGAL 12 ANOS 1L | C34: OK | E34: =IF(B34="","",IFERROR(MATCH(B34,CUSTOS!$A:$A,0),"NÃO ACHOU")) -> 195
A35: ='99'!A35 -> Licor Ballena Coco 750ML | B35: LICOR BALLENA COCO 750ML | C35: OK | E35: =IF(B35="","",IFERROR(MATCH(B35,CUSTOS!$A:$A,0),"NÃO ACHOU")) -> 564
A36: ='99'!A36 -> Fireball 750ml | B36: WHISKY FIREBALL 750ML | C36: OK | E36: =IF(B36="","",IFERROR(MATCH(B36,CUSTOS!$A:$A,0),"NÃO ACHOU")) -> 196
A37: ='99'!A37 -> Tequila Jose Cuervo Ouro Especial 750 ml | B37: TEQUILA JOSE CUERVO GOLD 750ML | C37: OK | E37: =IF(B37="","",IFERROR(MATCH(B37,CUSTOS!$A:$A,0),"NÃO ACHOU")) -> 81
A38: ='99'!A38 -> Gelo Fast Embalagem 5Kg | B38: FAST GELO 5KG | C38: OK | E38: =IF(B38="","",IFERROR(MATCH(B38,CUSTOS!$A:$A,0),"NÃO ACHOU")) -> 374
A39: ='99'!A39 -> Refresco H2oh Limão Pet com 1,5l | B39: AGUA SABORIZADA H2OH LIMÃO 1,5L | C39: OK | E39: =IF(B39="","",IFERROR(MATCH(B39,CUSTOS!$A:$A,0),"NÃO ACHOU")) -> 46
A40: ='99'!A40 -> Cerveja Eisenbahn Pilsen Lata 350ml | B40: Eisenbahn Pilsen Puro Malte 350ml | C40: OK | E40: =IF(B40="","",IFERROR(MATCH(B40,CUSTOS!$A:$A,0),"NÃO ACHOU")) -> 684
...
